2020-11-27 13:09:02,356 ERROR: Exception on /login [POST] [in /Users/maximefranchot/PycharmProjects/XY_Backend/venv/lib/python3.8/site-packages/flask/app.py:1891]
Traceback (most recent call last):
  File "/Users/maximefranchot/PycharmProjects/XY_Backend/venv/lib/python3.8/site-packages/flask/app.py", line 2447, in wsgi_app
    response = self.full_dispatch_request()
  File "/Users/maximefranchot/PycharmProjects/XY_Backend/venv/lib/python3.8/site-packages/flask/app.py", line 1952, in full_dispatch_request
    rv = self.handle_user_exception(e)
  File "/Users/maximefranchot/PycharmProjects/XY_Backend/venv/lib/python3.8/site-packages/flask/app.py", line 1821, in handle_user_exception
    reraise(exc_type, exc_value, tb)
  File "/Users/maximefranchot/PycharmProjects/XY_Backend/venv/lib/python3.8/site-packages/flask/_compat.py", line 39, in reraise
    raise value
  File "/Users/maximefranchot/PycharmProjects/XY_Backend/venv/lib/python3.8/site-packages/flask/app.py", line 1950, in full_dispatch_request
    rv = self.dispatch_request()
  File "/Users/maximefranchot/PycharmProjects/XY_Backend/venv/lib/python3.8/site-packages/flask/app.py", line 1936, in dispatch_request
    return self.view_functions[rule.endpoint](**req.view_args)
  File "/Users/maximefranchot/PycharmProjects/XY_Backend/app/routes.py", line 80, in login
    print(jsonify(request))
  File "/Users/maximefranchot/PycharmProjects/XY_Backend/venv/lib/python3.8/site-packages/flask/json/__init__.py", line 370, in jsonify
    dumps(data, indent=indent, separators=separators) + "\n",
  File "/Users/maximefranchot/PycharmProjects/XY_Backend/venv/lib/python3.8/site-packages/flask/json/__init__.py", line 211, in dumps
    rv = _json.dumps(obj, **kwargs)
  File "/Applications/Xcode.app/Contents/Developer/Library/Frameworks/Python3.framework/Versions/3.8/lib/python3.8/json/__init__.py", line 234, in dumps
    return cls(
  File "/Applications/Xcode.app/Contents/Developer/Library/Frameworks/Python3.framework/Versions/3.8/lib/python3.8/json/encoder.py", line 199, in encode
    chunks = self.iterencode(o, _one_shot=True)
  File "/Applications/Xcode.app/Contents/Developer/Library/Frameworks/Python3.framework/Versions/3.8/lib/python3.8/json/encoder.py", line 257, in iterencode
    return _iterencode(o, 0)
  File "/Users/maximefranchot/PycharmProjects/XY_Backend/venv/lib/python3.8/site-packages/flask/json/__init__.py", line 100, in default
    return _json.JSONEncoder.default(self, o)
  File "/Applications/Xcode.app/Contents/Developer/Library/Frameworks/Python3.framework/Versions/3.8/lib/python3.8/json/encoder.py", line 179, in default
    raise TypeError(f'Object of type {o.__class__.__name__} '
TypeError: Object of type LocalProxy is not JSON serializable
2020-11-27 13:10:06,954 INFO: Microblog startup [in /Users/maximefranchot/PycharmProjects/XY_Backend/app/__init__.py:49]
2020-11-27 13:10:20,528 ERROR: Exception on /login [POST] [in /Users/maximefranchot/PycharmProjects/XY_Backend/venv/lib/python3.8/site-packages/flask/app.py:1891]
Traceback (most recent call last):
  File "/Users/maximefranchot/PycharmProjects/XY_Backend/venv/lib/python3.8/site-packages/flask/app.py", line 2447, in wsgi_app
    response = self.full_dispatch_request()
  File "/Users/maximefranchot/PycharmProjects/XY_Backend/venv/lib/python3.8/site-packages/flask/app.py", line 1952, in full_dispatch_request
    rv = self.handle_user_exception(e)
  File "/Users/maximefranchot/PycharmProjects/XY_Backend/venv/lib/python3.8/site-packages/flask/app.py", line 1821, in handle_user_exception
    reraise(exc_type, exc_value, tb)
  File "/Users/maximefranchot/PycharmProjects/XY_Backend/venv/lib/python3.8/site-packages/flask/_compat.py", line 39, in reraise
    raise value
  File "/Users/maximefranchot/PycharmProjects/XY_Backend/venv/lib/python3.8/site-packages/flask/app.py", line 1950, in full_dispatch_request
    rv = self.dispatch_request()
  File "/Users/maximefranchot/PycharmProjects/XY_Backend/venv/lib/python3.8/site-packages/flask/app.py", line 1936, in dispatch_request
    return self.view_functions[rule.endpoint](**req.view_args)
  File "/Users/maximefranchot/PycharmProjects/XY_Backend/app/routes.py", line 82, in login
    print(json.dumps(request))
  File "/Applications/Xcode.app/Contents/Developer/Library/Frameworks/Python3.framework/Versions/3.8/lib/python3.8/json/__init__.py", line 231, in dumps
    return _default_encoder.encode(obj)
  File "/Applications/Xcode.app/Contents/Developer/Library/Frameworks/Python3.framework/Versions/3.8/lib/python3.8/json/encoder.py", line 199, in encode
    chunks = self.iterencode(o, _one_shot=True)
  File "/Applications/Xcode.app/Contents/Developer/Library/Frameworks/Python3.framework/Versions/3.8/lib/python3.8/json/encoder.py", line 257, in iterencode
    return _iterencode(o, 0)
  File "/Applications/Xcode.app/Contents/Developer/Library/Frameworks/Python3.framework/Versions/3.8/lib/python3.8/json/encoder.py", line 179, in default
    raise TypeError(f'Object of type {o.__class__.__name__} '
TypeError: Object of type LocalProxy is not JSON serializable
2020-11-27 13:10:42,063 INFO: Microblog startup [in /Users/maximefranchot/PycharmProjects/XY_Backend/app/__init__.py:49]
2020-11-27 13:11:24,978 INFO: Microblog startup [in /Users/maximefranchot/PycharmProjects/XY_Backend/app/__init__.py:49]
2020-11-27 13:11:38,752 ERROR: Exception on /login [POST] [in /Users/maximefranchot/PycharmProjects/XY_Backend/venv/lib/python3.8/site-packages/flask/app.py:1891]
Traceback (most recent call last):
  File "/Users/maximefranchot/PycharmProjects/XY_Backend/venv/lib/python3.8/site-packages/flask/app.py", line 2447, in wsgi_app
    response = self.full_dispatch_request()
  File "/Users/maximefranchot/PycharmProjects/XY_Backend/venv/lib/python3.8/site-packages/flask/app.py", line 1952, in full_dispatch_request
    rv = self.handle_user_exception(e)
  File "/Users/maximefranchot/PycharmProjects/XY_Backend/venv/lib/python3.8/site-packages/flask/app.py", line 1821, in handle_user_exception
    reraise(exc_type, exc_value, tb)
  File "/Users/maximefranchot/PycharmProjects/XY_Backend/venv/lib/python3.8/site-packages/flask/_compat.py", line 39, in reraise
    raise value
  File "/Users/maximefranchot/PycharmProjects/XY_Backend/venv/lib/python3.8/site-packages/flask/app.py", line 1950, in full_dispatch_request
    rv = self.dispatch_request()
  File "/Users/maximefranchot/PycharmProjects/XY_Backend/venv/lib/python3.8/site-packages/flask/app.py", line 1936, in dispatch_request
    return self.view_functions[rule.endpoint](**req.view_args)
  File "/Users/maximefranchot/PycharmProjects/XY_Backend/app/routes.py", line 82, in login
    print(request.data.message)
AttributeError: 'bytes' object has no attribute 'message'
2020-11-27 13:12:28,388 INFO: Microblog startup [in /Users/maximefranchot/PycharmProjects/XY_Backend/app/__init__.py:49]
2020-11-27 13:12:58,250 INFO: Microblog startup [in /Users/maximefranchot/PycharmProjects/XY_Backend/app/__init__.py:49]
2020-11-27 13:13:36,902 INFO: Microblog startup [in /Users/maximefranchot/PycharmProjects/XY_Backend/app/__init__.py:49]
2020-11-27 13:13:44,035 ERROR: Exception on /login [POST] [in /Users/maximefranchot/PycharmProjects/XY_Backend/venv/lib/python3.8/site-packages/flask/app.py:1891]
Traceback (most recent call last):
  File "/Users/maximefranchot/PycharmProjects/XY_Backend/venv/lib/python3.8/site-packages/flask/app.py", line 2447, in wsgi_app
    response = self.full_dispatch_request()
  File "/Users/maximefranchot/PycharmProjects/XY_Backend/venv/lib/python3.8/site-packages/flask/app.py", line 1952, in full_dispatch_request
    rv = self.handle_user_exception(e)
  File "/Users/maximefranchot/PycharmProjects/XY_Backend/venv/lib/python3.8/site-packages/flask/app.py", line 1821, in handle_user_exception
    reraise(exc_type, exc_value, tb)
  File "/Users/maximefranchot/PycharmProjects/XY_Backend/venv/lib/python3.8/site-packages/flask/_compat.py", line 39, in reraise
    raise value
  File "/Users/maximefranchot/PycharmProjects/XY_Backend/venv/lib/python3.8/site-packages/flask/app.py", line 1950, in full_dispatch_request
    rv = self.dispatch_request()
  File "/Users/maximefranchot/PycharmProjects/XY_Backend/venv/lib/python3.8/site-packages/flask/app.py", line 1936, in dispatch_request
    return self.view_functions[rule.endpoint](**req.view_args)
  File "/Users/maximefranchot/PycharmProjects/XY_Backend/app/routes.py", line 84, in login
    print(requestDecoded['message'])
TypeError: string indices must be integers
2020-11-27 13:14:42,063 ERROR: Exception on /login [POST] [in /Users/maximefranchot/PycharmProjects/XY_Backend/venv/lib/python3.8/site-packages/flask/app.py:1891]
Traceback (most recent call last):
  File "/Users/maximefranchot/PycharmProjects/XY_Backend/venv/lib/python3.8/site-packages/flask/app.py", line 2447, in wsgi_app
    response = self.full_dispatch_request()
  File "/Users/maximefranchot/PycharmProjects/XY_Backend/venv/lib/python3.8/site-packages/flask/app.py", line 1952, in full_dispatch_request
    rv = self.handle_user_exception(e)
  File "/Users/maximefranchot/PycharmProjects/XY_Backend/venv/lib/python3.8/site-packages/flask/app.py", line 1821, in handle_user_exception
    reraise(exc_type, exc_value, tb)
  File "/Users/maximefranchot/PycharmProjects/XY_Backend/venv/lib/python3.8/site-packages/flask/_compat.py", line 39, in reraise
    raise value
  File "/Users/maximefranchot/PycharmProjects/XY_Backend/venv/lib/python3.8/site-packages/flask/app.py", line 1950, in full_dispatch_request
    rv = self.dispatch_request()
  File "/Users/maximefranchot/PycharmProjects/XY_Backend/venv/lib/python3.8/site-packages/flask/app.py", line 1936, in dispatch_request
    return self.view_functions[rule.endpoint](**req.view_args)
  File "/Users/maximefranchot/PycharmProjects/XY_Backend/app/routes.py", line 84, in login
    print(requestDecoded['message'])
TypeError: string indices must be integers
2020-11-27 13:15:02,040 INFO: Microblog startup [in /Users/maximefranchot/PycharmProjects/XY_Backend/app/__init__.py:49]
