2020-11-27 15:25:18,128 ERROR: Exception on /register [POST] [in /Users/maximefranchot/PycharmProjects/XY_Backend/venv/lib/python3.8/site-packages/flask/app.py:1891]
Traceback (most recent call last):
  File "/Users/maximefranchot/PycharmProjects/XY_Backend/venv/lib/python3.8/site-packages/sqlalchemy/engine/base.py", line 1276, in _execute_context
    self.dialect.do_execute(
  File "/Users/maximefranchot/PycharmProjects/XY_Backend/venv/lib/python3.8/site-packages/sqlalchemy/engine/default.py", line 593, in do_execute
    cursor.execute(statement, parameters)
sqlite3.IntegrityError: UNIQUE constraint failed: user.email

The above exception was the direct cause of the following exception:

Traceback (most recent call last):
  File "/Users/maximefranchot/PycharmProjects/XY_Backend/venv/lib/python3.8/site-packages/flask/app.py", line 2447, in wsgi_app
    response = self.full_dispatch_request()
  File "/Users/maximefranchot/PycharmProjects/XY_Backend/venv/lib/python3.8/site-packages/flask/app.py", line 1952, in full_dispatch_request
    rv = self.handle_user_exception(e)
  File "/Users/maximefranchot/PycharmProjects/XY_Backend/venv/lib/python3.8/site-packages/flask/app.py", line 1821, in handle_user_exception
    reraise(exc_type, exc_value, tb)
  File "/Users/maximefranchot/PycharmProjects/XY_Backend/venv/lib/python3.8/site-packages/flask/_compat.py", line 39, in reraise
    raise value
  File "/Users/maximefranchot/PycharmProjects/XY_Backend/venv/lib/python3.8/site-packages/flask/app.py", line 1950, in full_dispatch_request
    rv = self.dispatch_request()
  File "/Users/maximefranchot/PycharmProjects/XY_Backend/venv/lib/python3.8/site-packages/flask/app.py", line 1936, in dispatch_request
    return self.view_functions[rule.endpoint](**req.view_args)
  File "/Users/maximefranchot/PycharmProjects/XY_Backend/app/routes.py", line 131, in register
    db.session.commit()
  File "/Users/maximefranchot/PycharmProjects/XY_Backend/venv/lib/python3.8/site-packages/sqlalchemy/orm/scoping.py", line 163, in do
    return getattr(self.registry(), name)(*args, **kwargs)
  File "/Users/maximefranchot/PycharmProjects/XY_Backend/venv/lib/python3.8/site-packages/sqlalchemy/orm/session.py", line 1042, in commit
    self.transaction.commit()
  File "/Users/maximefranchot/PycharmProjects/XY_Backend/venv/lib/python3.8/site-packages/sqlalchemy/orm/session.py", line 504, in commit
    self._prepare_impl()
  File "/Users/maximefranchot/PycharmProjects/XY_Backend/venv/lib/python3.8/site-packages/sqlalchemy/orm/session.py", line 483, in _prepare_impl
    self.session.flush()
  File "/Users/maximefranchot/PycharmProjects/XY_Backend/venv/lib/python3.8/site-packages/sqlalchemy/orm/session.py", line 2536, in flush
    self._flush(objects)
  File "/Users/maximefranchot/PycharmProjects/XY_Backend/venv/lib/python3.8/site-packages/sqlalchemy/orm/session.py", line 2678, in _flush
    transaction.rollback(_capture_exception=True)
  File "/Users/maximefranchot/PycharmProjects/XY_Backend/venv/lib/python3.8/site-packages/sqlalchemy/util/langhelpers.py", line 68, in __exit__
    compat.raise_(
  File "/Users/maximefranchot/PycharmProjects/XY_Backend/venv/lib/python3.8/site-packages/sqlalchemy/util/compat.py", line 182, in raise_
    raise exception
  File "/Users/maximefranchot/PycharmProjects/XY_Backend/venv/lib/python3.8/site-packages/sqlalchemy/orm/session.py", line 2638, in _flush
    flush_context.execute()
  File "/Users/maximefranchot/PycharmProjects/XY_Backend/venv/lib/python3.8/site-packages/sqlalchemy/orm/unitofwork.py", line 422, in execute
    rec.execute(self)
  File "/Users/maximefranchot/PycharmProjects/XY_Backend/venv/lib/python3.8/site-packages/sqlalchemy/orm/unitofwork.py", line 586, in execute
    persistence.save_obj(
  File "/Users/maximefranchot/PycharmProjects/XY_Backend/venv/lib/python3.8/site-packages/sqlalchemy/orm/persistence.py", line 239, in save_obj
    _emit_insert_statements(
  File "/Users/maximefranchot/PycharmProjects/XY_Backend/venv/lib/python3.8/site-packages/sqlalchemy/orm/persistence.py", line 1135, in _emit_insert_statements
    result = cached_connections[connection].execute(
  File "/Users/maximefranchot/PycharmProjects/XY_Backend/venv/lib/python3.8/site-packages/sqlalchemy/engine/base.py", line 1011, in execute
    return meth(self, multiparams, params)
  File "/Users/maximefranchot/PycharmProjects/XY_Backend/venv/lib/python3.8/site-packages/sqlalchemy/sql/elements.py", line 298, in _execute_on_connection
    return connection._execute_clauseelement(self, multiparams, params)
  File "/Users/maximefranchot/PycharmProjects/XY_Backend/venv/lib/python3.8/site-packages/sqlalchemy/engine/base.py", line 1124, in _execute_clauseelement
    ret = self._execute_context(
  File "/Users/maximefranchot/PycharmProjects/XY_Backend/venv/lib/python3.8/site-packages/sqlalchemy/engine/base.py", line 1316, in _execute_context
    self._handle_dbapi_exception(
  File "/Users/maximefranchot/PycharmProjects/XY_Backend/venv/lib/python3.8/site-packages/sqlalchemy/engine/base.py", line 1510, in _handle_dbapi_exception
    util.raise_(
  File "/Users/maximefranchot/PycharmProjects/XY_Backend/venv/lib/python3.8/site-packages/sqlalchemy/util/compat.py", line 182, in raise_
    raise exception
  File "/Users/maximefranchot/PycharmProjects/XY_Backend/venv/lib/python3.8/site-packages/sqlalchemy/engine/base.py", line 1276, in _execute_context
    self.dialect.do_execute(
  File "/Users/maximefranchot/PycharmProjects/XY_Backend/venv/lib/python3.8/site-packages/sqlalchemy/engine/default.py", line 593, in do_execute
    cursor.execute(statement, parameters)
sqlalchemy.exc.IntegrityError: (sqlite3.IntegrityError) UNIQUE constraint failed: user.email
[SQL: INSERT INTO user (username, email, password_hash, about_me, last_seen) VALUES (?, ?, ?, ?, ?)]
[parameters: ('maxime2', 'maxrofra@gmail.com', 'pbkdf2:sha256:150000$tUcuFhAU$e604f053e0900ea23a9f325eda9dab9f52324d6c5dd7cb36ff20e81e16a6e735', None, '2020-11-27 14:25:18.127763')]
(Background on this error at: http://sqlalche.me/e/13/gkpj)
2020-11-27 15:27:35,758 INFO: Microblog startup [in /Users/maximefranchot/PycharmProjects/XY_Backend/app/__init__.py:49]
2020-11-27 15:28:39,327 ERROR: Exception on /register [POST] [in /Users/maximefranchot/PycharmProjects/XY_Backend/venv/lib/python3.8/site-packages/flask/app.py:1891]
Traceback (most recent call last):
  File "/Users/maximefranchot/PycharmProjects/XY_Backend/venv/lib/python3.8/site-packages/flask/app.py", line 2447, in wsgi_app
    response = self.full_dispatch_request()
  File "/Users/maximefranchot/PycharmProjects/XY_Backend/venv/lib/python3.8/site-packages/flask/app.py", line 1953, in full_dispatch_request
    return self.finalize_request(rv)
  File "/Users/maximefranchot/PycharmProjects/XY_Backend/venv/lib/python3.8/site-packages/flask/app.py", line 1968, in finalize_request
    response = self.make_response(rv)
  File "/Users/maximefranchot/PycharmProjects/XY_Backend/venv/lib/python3.8/site-packages/flask/app.py", line 2112, in make_response
    rv = jsonify(rv)
  File "/Users/maximefranchot/PycharmProjects/XY_Backend/venv/lib/python3.8/site-packages/flask/json/__init__.py", line 370, in jsonify
    dumps(data, indent=indent, separators=separators) + "\n",
  File "/Users/maximefranchot/PycharmProjects/XY_Backend/venv/lib/python3.8/site-packages/flask/json/__init__.py", line 211, in dumps
    rv = _json.dumps(obj, **kwargs)
  File "/Applications/Xcode.app/Contents/Developer/Library/Frameworks/Python3.framework/Versions/3.8/lib/python3.8/json/__init__.py", line 234, in dumps
    return cls(
  File "/Applications/Xcode.app/Contents/Developer/Library/Frameworks/Python3.framework/Versions/3.8/lib/python3.8/json/encoder.py", line 199, in encode
    chunks = self.iterencode(o, _one_shot=True)
  File "/Applications/Xcode.app/Contents/Developer/Library/Frameworks/Python3.framework/Versions/3.8/lib/python3.8/json/encoder.py", line 257, in iterencode
    return _iterencode(o, 0)
  File "/Users/maximefranchot/PycharmProjects/XY_Backend/venv/lib/python3.8/site-packages/flask/json/__init__.py", line 100, in default
    return _json.JSONEncoder.default(self, o)
  File "/Applications/Xcode.app/Contents/Developer/Library/Frameworks/Python3.framework/Versions/3.8/lib/python3.8/json/encoder.py", line 179, in default
    raise TypeError(f'Object of type {o.__class__.__name__} '
TypeError: Object of type bytes is not JSON serializable
2020-11-27 15:30:45,005 INFO: Microblog startup [in /Users/maximefranchot/PycharmProjects/XY_Backend/app/__init__.py:49]
2020-11-27 15:32:26,688 INFO: Microblog startup [in /Users/maximefranchot/PycharmProjects/XY_Backend/app/__init__.py:49]
2020-11-27 15:32:51,144 ERROR: Exception on /register [POST] [in /Users/maximefranchot/PycharmProjects/XY_Backend/venv/lib/python3.8/site-packages/flask/app.py:1891]
Traceback (most recent call last):
  File "/Users/maximefranchot/PycharmProjects/XY_Backend/venv/lib/python3.8/site-packages/flask/app.py", line 2447, in wsgi_app
    response = self.full_dispatch_request()
  File "/Users/maximefranchot/PycharmProjects/XY_Backend/venv/lib/python3.8/site-packages/flask/app.py", line 1952, in full_dispatch_request
    rv = self.handle_user_exception(e)
  File "/Users/maximefranchot/PycharmProjects/XY_Backend/venv/lib/python3.8/site-packages/flask/app.py", line 1821, in handle_user_exception
    reraise(exc_type, exc_value, tb)
  File "/Users/maximefranchot/PycharmProjects/XY_Backend/venv/lib/python3.8/site-packages/flask/_compat.py", line 39, in reraise
    raise value
  File "/Users/maximefranchot/PycharmProjects/XY_Backend/venv/lib/python3.8/site-packages/flask/app.py", line 1950, in full_dispatch_request
    rv = self.dispatch_request()
  File "/Users/maximefranchot/PycharmProjects/XY_Backend/venv/lib/python3.8/site-packages/flask/app.py", line 1936, in dispatch_request
    return self.view_functions[rule.endpoint](**req.view_args)
  File "/Users/maximefranchot/PycharmProjects/XY_Backend/app/routes.py", line 124, in register
    form.validate_email()
TypeError: validate_email() missing 1 required positional argument: 'email'
